model
name = BETTER CALL SAUL
revision = 8418
size = 22 40 21
origin = -y
shell = Outline 0.25
material type = toon, lighting = smooth, deform = 1 1
  colors = E:#2F19BE F:#3E2723 C:#FFE3EC
material type = basic, lighting = smooth, roughness = 0, refractionRatio = 1, side = back
  colors = Outline:#000
voxels
1299-13(20E2-)4(3(19E3-)4(20E2-)20E420-6(20E2-)4(19E3-)3(20E2-))2(7(20E2-)20E420-6(20E2-)4(19E3-)3(19EC2-))5(3(20E2-)3(19EC2-)20E2-20E420-6(20E2-)4(19E3-)3(19EC2-))2(7(20E2-)20E420-6(20E2-)4(19E3-)3(19EC2-))2(3(20E2-)3(19EC2-)20E2-20E420-6(20E2-)4(19E3-)3(19EC2-))3(20E2-)2(3(19EC2-)20E2-20E420-6(20E2-)4(19E3-)6(20E2-))4(20E2-)20E420-6(20E2-)4(19E3-)10(20E2-)20E420-2(20E2-)E4F15E2-E16F3E2-E4F4C7EF3E2-E3F2C3E2C5EF3E2-2E3F5E2C4EF3E2-2E3F7E2C2EF3E2-2E2F4E3F2E2CEF3E2-2E2F2E2(3FE)2CF3E2-2E13FCF3E2-2E3(3FE)3F3E2-2E7FE5FC2F2E2-2E13F2EF2E2-2E7FE8F2E2-2E5FC3FC4FEF2E2-3E15F2E2-3EF16E3(2-20E)-
