model
name = BETTER CALL SAUL
revision = 8423
size = 22 40 21
origin = -y
shell = Outline 0.25
material type = toon, lighting = smooth, deform = 1 1
  colors = E:#2F19BE F:#3E2723 C:#FFE3EC
material type = basic, lighting = smooth, roughness = 0, refractionRatio = 1, side = back
  colors = Outline:#000
voxels
1299-13(20E2-)4(3(19E3-)4(20E2-)20E420-6(20E2-)4(19E3-)3(20E2-))2(7(20E2-)20E420-6(20E2-)4(19E3-)3(19EC2-))5(3(20E2-)3(19EC2-)20E2-20E420-6(20E2-)4(19E3-)3(19EC2-))2(7(20E2-)20E420-6(20E2-)4(19E3-)3(19EC2-))2(3(20E2-)3(19EC2-)20E2-20E420-6(20E2-)4(19E3-)3(19EC2-))3(20E2-)2(3(19EC2-)20E2-20E420-6(20E2-)4(19E3-)6(20E2-))4(20E2-)20E420-6(20E2-)4(19E3-)10(20E2-)20E420-2(20E2-)15(E17F2E2-)E3F16E3(2-20E)-
