model
name = BETTER CALL SAUL
revision = 8414
size = 22 40 21
origin = -y
shell = Outline 0.25
material type = toon, lighting = smooth, deform = 1 1
  colors = E:#2F19BE C:#FFE3EC
material type = basic, lighting = smooth, roughness = 0, refractionRatio = 1, side = back
  colors = Outline:#000
voxels
1299-13(20E2-)4(3(19E3-)4(20E2-)20E420-6(20E2-)4(19E3-)3(20E2-))2(7(20E2-)20E420-6(20E2-)4(19E3-)3(19EC2-))5(3(20E2-)3(19EC2-)20E2-20E420-6(20E2-)4(19E3-)3(19EC2-))2(7(20E2-)20E420-6(20E2-)4(19E3-)3(19EC2-))2(3(20E2-)3(19EC2-)20E2-20E420-6(20E2-)4(19E3-)3(19EC2-))3(20E2-)2(3(19EC2-)20E2-20E420-6(20E2-)4(19E3-)6(20E2-))4(20E2-)20E420-6(20E2-)4(19E3-)10(20E2-)20E420-4(20E2-)5E4C11E2-3E3C3E2C9E2-2E2C6E2C8E2-2EC9E2C6E2-2EC10E2C5E2-2EC11E2C4E2-2EC12EC4E2-3EC11EC4E2-3E2C8E3C4E2-4EC6E3C6E2-5E2C4E2C7E2-6E2C3EC8E2-7E6C7E4(2-20E)-
